<?xml version="1.0"?>
<sdf version="1.6">
    <model name="rmf_owl" canonical_link="base_link">
        <pose>0 0 0.15 0 -0 0</pose>
    
        <!-- Links and Joints -->
        <link name="base_link">
            <pose frame="">0 0 0 0 -0 0</pose>
            <inertial>
                <pose frame="">0 0 0 0 -0 0</pose>
                <mass>1.46</mass>
                <inertia>
                    <ixx>0.017</ixx>
                    <ixy>0</ixy>
                    <ixz>0</ixz>
                    <iyy>0.018</iyy>
                    <iyz>0</iyz>
                    <izz>0.028</izz>
                </inertia>
            </inertial>
            <collision name="base_link_inertia_collision">
                <pose frame="">0 0 0 0 -0 0</pose>
                <geometry>
                    <mesh>
                        <scale>1 1 1</scale>
                        <uri>meshes/rmf_owl.dae</uri>
                    </mesh>
                </geometry>
            </collision>
            <visual name="base_link_inertia_visual">
                <pose frame="">0 0 0 0 -0 0</pose>
                <geometry>
                    <mesh>
                        <scale>1 1 1</scale>
                        <uri>meshes/rmf_owl.dae</uri>
                    </mesh>
                </geometry>
            </visual>

            <!-- Sensors -->
            <sensor name="imu_sensor" type="imu">
                <always_on>1</always_on>
                <update_rate>200</update_rate>          
                <visualize>true</visualize>
                <topic>rmf_owl/imu</topic>
                <imu>
                    <angular_velocity>
                        <x>
                            <noise type="gaussian">
                                <mean>0</mean>
                                <stddev>0.009</stddev>
                                <bias_mean>0.00075</bias_mean>
                                <bias_stddev>0.005</bias_stddev>
                                <dynamic_bias_stddev>0.00002</dynamic_bias_stddev>
                                <dynamic_bias_correlation_time>400.0</dynamic_bias_correlation_time>
                                <precision>0.00025</precision>
                            </noise>
                        </x>
                        <y>
                            <noise type="gaussian">
                                <mean>0</mean>
                                <stddev>0.009</stddev>
                                <bias_mean>0.00075</bias_mean>
                                <bias_stddev>0.005</bias_stddev>
                                <dynamic_bias_stddev>0.00002</dynamic_bias_stddev>
                                <dynamic_bias_correlation_time>400.0</dynamic_bias_correlation_time>
                                <precision>0.00025</precision>
                            </noise>
                        </y>
                        <z>
                            <noise type="gaussian">
                                <mean>0</mean>
                                <stddev>0.009</stddev>
                                <bias_mean>0.00075</bias_mean>
                                <bias_stddev>0.005</bias_stddev>
                                <dynamic_bias_stddev>0.00002</dynamic_bias_stddev>
                                <dynamic_bias_correlation_time>400.0</dynamic_bias_correlation_time>
                                <precision>0.00025</precision>
                            </noise>
                        </z>
                    </angular_velocity>
                    <linear_acceleration>
                        <x>
                            <noise type="gaussian">
                                <mean>0</mean>
                                <stddev>0.021</stddev>
                                <bias_mean>0.05</bias_mean>
                                <bias_stddev>0.0075</bias_stddev>
                                <dynamic_bias_stddev>0.000375</dynamic_bias_stddev>
                                <dynamic_bias_correlation_time>175.0</dynamic_bias_correlation_time>
                                <precision>0.005</precision>
                            </noise>
                        </x>
                        <y>
                            <noise type="gaussian">
                                <mean>0</mean>
                                <stddev>0.021</stddev>
                                <bias_mean>0.05</bias_mean>
                                <bias_stddev>0.0075</bias_stddev>
                                <dynamic_bias_stddev>0.000375</dynamic_bias_stddev>
                                <dynamic_bias_correlation_time>175.0</dynamic_bias_correlation_time>
                                <precision>0.005</precision>
                            </noise>
                        </y>
                        <z>
                            <noise type="gaussian">
                                <mean>0</mean>
                                <stddev>0.021</stddev>
                                <bias_mean>0.05</bias_mean>
                                <bias_stddev>0.0075</bias_stddev>
                                <dynamic_bias_stddev>0.000375</dynamic_bias_stddev>
                                <dynamic_bias_correlation_time>175.0</dynamic_bias_correlation_time>
                                <precision>0.005</precision>
                            </noise>
                        </z>
                    </linear_acceleration>
                    <enable_orientation>0</enable_orientation>
                </imu>
            </sensor>
            <sensor name="air_pressure" type="air_pressure"> 
                <always_on>1</always_on> 
                <update_rate>20</update_rate> 
                <air_pressure> 
                    <reference_altitude>0</reference_altitude> 
                    <noise type="gaussian">
                        <mean>0.00000008</mean>
                    </noise>
                </air_pressure>
            </sensor>
            <sensor name="magnetometer" type="magnetometer">
                <always_on>1</always_on>
                <update_rate>20</update_rate>
                <magnetometer>
                    <x>
                        <noise type="gaussian">
                            <mean>0.000000080</mean>
                            <bias_mean>0.000000400</bias_mean>
                        </noise>
                    </x>
                    <y>
                        <noise type="gaussian">
                            <mean>0.000000080</mean>
                            <bias_mean>0.000000400</bias_mean>
                        </noise>
                    </y>
                    <z>
                        <noise type="gaussian">
                            <mean>0.000000080</mean>
                            <bias_mean>0.000000400</bias_mean>
                        </noise>
                    </z>
                </magnetometer>
            </sensor>
            <sensor name="camera_front" type="camera">
                <!-- <pose>0.180 0 -0.025 0 0.785398 0</pose> -->
                <pose>0.180 0 -0.025 0 0.0 0</pose>
                <always_on>1</always_on>
                <update_rate>20</update_rate>
                <visualize>true</visualize>
                <camera name="camera_front">
                    <horizontal_fov>2.0944</horizontal_fov>
                    <lens>
                        <intrinsics>
                            <fx>1108.952913</fx>
                            <fy>1110.658360</fy>
                            <cx>729.533992</cx>
                            <cy>544.985715</cy>
                            <s>1</s>
                        </intrinsics>
                    </lens>
                    <distortion>
                        <k1>0.0</k1>
                        <k2>0.0</k2>
                        <k3>0.0</k3>
                        <p1>0.0</p1>
                        <p2>0.0</p2>
                        <center>0.5 0.5</center>
                    </distortion>
                    <image>
                        <width>1440</width>
                        <height>1080</height>
                        <format>R8G8B8</format>
                    </image>
                    <clip>
                        <near>0.02</near>
                        <far>20</far>
                    </clip>
                    <noise>
                        <type>gaussian</type>
                        <mean>0</mean>
                        <stddev>0.007</stddev>
                    </noise>
                </camera>
            </sensor>
            <!-- <visual name="camera_visual">
                <pose>0.08 -0.032 0.10 0 -0.261799 0</pose>
                <geometry>
                    <box>
                        <size>0.02 0.025 0.025</size>
                    </box>
                </geometry>
            </visual> -->
        </link>
        <link name="camera_link">
            <pose>0.25 0 0.0 0 0.0 0</pose>
            <inertial>
                <pose>0 0 0 0 0 0</pose>
                <mass>0.001</mass>
                <inertia>
                    <ixx>0.000461625</ixx>
                    <ixy>0</ixy>
                    <ixz>0</ixz>
                    <iyy>0.000461625</iyy>
                    <iyz>0</iyz>
                    <izz>0.000473063</izz>
                </inertia>
            </inertial>
            <collision name="camera_collision">
                <pose>0.25 0 0.0 0 0.0 0</pose>
                <geometry>
                <cylinder>
                    <length>0.001</length>
                    <radius>0.001</radius>
                </cylinder>
                </geometry>
            </collision>
            <visual name="camera_visual">
                <pose>0.0 -0.0 0. 0 -0. 0</pose>
                <geometry>
                    <cylinder>
                        <length>0.001</length>
                        <radius>0.001</radius>
                    </cylinder>
                </geometry>
            </visual>
            <gravity>1</gravity>
            <velocity_decay/>
            <sensor name="depth_camera_front" type="depth_camera">
                <!-- <pose>0.180 0 -0.025 0 0.785398 0</pose> -->
                <pose>0 0 0 0 0 0</pose>
                <always_on>1</always_on>
                <update_rate>20</update_rate>
                <visualize>true</visualize>
                <camera name="depth_camera_front">
                    <horizontal_fov>1.518</horizontal_fov>
                    <lens>
                        <intrinsics>
                            <fx>74.94</fx>
                            <fy>74.94</fy>
                            <cx>48</cx>
                            <cy>27</cy>
                            <s>1</s>
                        </intrinsics>
                    </lens>
                    <image>
                        <width>96</width>
                        <height>54</height>
                        <format>R_FLOAT32</format>
                    </image>
                    <clip>
                        <near>0.2</near>
                        <far>15</far>
                    </clip>
                    <noise>
                        <type>gaussian</type>
                        <mean>0</mean>
                        <stddev>0.007</stddev>
                    </noise>
                </camera>
            </sensor>
        </link>
        <joint name="camera_joint_pitch" type="revolute">
            <child>camera_link</child>
            <parent>base_link</parent>
            <axis>
                <dynamics>
                <spring_reference>0</spring_reference>
                <spring_stiffness>0.02</spring_stiffness>
                </dynamics>
                <xyz>0 1 0</xyz>
                <use_parent_model_frame>0</use_parent_model_frame>
                <limit>
                    <lower>-1e+16</lower>
                    <upper>1e+16</upper>
                </limit>
            </axis>
        </joint>
        <link name="laser_link">
            <pose> 0 0 0.05 0 -0 0 </pose>
            <inertial>
                <pose>0 0 0.03675 0 -0 0</pose>
                <mass>0.5</mass>
                <inertia>
                    <ixx>0.000461625</ixx>
                    <ixy>0</ixy>
                    <ixz>0</ixz>
                    <iyy>0.000461625</iyy>
                    <iyz>0</iyz>
                    <izz>0.000473063</izz>
                </inertia>
            </inertial>
            <collision name="laser_collision">
                <pose>0 0 0.03675 0 -0 0</pose>
                <geometry>
                <cylinder>
                    <length>0.0735</length>
                    <radius>0.0435</radius>
                </cylinder>
                </geometry>
            </collision>
            <visual name="laser_visual">
                <geometry>
                <mesh>
                    <uri>ouster/ouster-os0.dae</uri>
                </mesh>
                </geometry>
            </visual>
            <gravity>1</gravity>
            <velocity_decay/>
            <sensor name="laser" type="gpu_lidar">
                <!-- <pose relative_to="base_link">0 0 0 0 -0 0</pose> -->
                <pose>0 0 0.035925 0 -0 0</pose>
                <topic>rmf_owl/lidar</topic>
                <update_rate>10</update_rate>
                <visualize>1</visualize>
                <always_on>1</always_on>
                <lidar>
                    <scan>
                        <horizontal>
                        <samples>2048</samples> 
                        <resolution>1</resolution>
                        <min_angle>-3.1459</min_angle>
                        <max_angle>3.1459</max_angle>
                        </horizontal>
                        <vertical>
                        <samples>128</samples>
                        <resolution>1</resolution>
                        <min_angle>-0.785398</min_angle>
                        <max_angle>0.785398</max_angle>
                        </vertical>
                    </scan>
                    <range>
                        <min>0.3</min>
                        <max>50</max>
                        <resolution>0.01</resolution>
                    </range>
                    <noise>
                        <type>gaussian</type>
                        <mean>0</mean>
                        <stddev>0.01</stddev>
                    </noise>
                </lidar>
            </sensor>
        </link>
        <joint name="laser_joint" type="fixed">
            <child>laser_link</child>
            <parent>base_link</parent>
            <axis>
                <dynamics>
                <spring_reference>0</spring_reference>
                <spring_stiffness>0</spring_stiffness>
                </dynamics>
                <xyz>0 0 1</xyz>
                <use_parent_model_frame>0</use_parent_model_frame>
                <limit>
                    <lower>-1e+16</lower>
                    <upper>1e+16</upper>
                </limit>
            </axis>
            <physics>
                <ode>
                <limit>
                    <cfm>0</cfm>
                    <erp>0.2</erp>
                </limit>
                </ode>
            </physics>
        </joint>
        <link name="rotor_0">
            <pose frame="">0.09 -0.09 -0.005 0 -0 0</pose>
            <inertial>
                <pose frame="">0 0 0 0 -0 0</pose>
                <mass>0.005</mass>
                <inertia>
                    <ixx>9.75e-07</ixx>
                    <ixy>0</ixy>
                    <ixz>0</ixz>
                    <iyy>8.13545e-05</iyy>
                    <iyz>0</iyz>
                    <izz>8.22545e-05</izz>
                </inertia>
            </inertial>
            <collision name="rotor_0_collision">
                <pose frame="">0 0 0 0 -0 0</pose>
                <geometry>
                    <cylinder>
                        <length>0.005</length>
                        <radius>0.06</radius>
                    </cylinder>
                </geometry>
                <surface>
                    <contact>
                        <ode />
                    </contact>
                    <friction>
                        <ode />
                    </friction>
                </surface>
            </collision>
            <visual name="rotor_0_visual">
                <pose frame="">0 0 0 0 -0 0</pose>
                <geometry>
                    <mesh>
                        <scale>1 1 1</scale>
                        <uri>meshes/propeller_ccw.dae</uri>
                    </mesh>
                </geometry>
                <material>
                    <diffuse>1 0 0 1</diffuse>
                    <script>
                        <name>Gazebo/Red</name>
                        <uri>file://media/materials/scripts/gazebo.material</uri>
                    </script>
                </material>
                <cast_shadows>0</cast_shadows>
            </visual>
            <gravity>1</gravity>
            <velocity_decay/>
        </link>
        <joint name="rotor_0_joint" type="revolute">
            <child>rotor_0</child>
            <parent>base_link</parent>
            <axis>
                <xyz>0 0 1</xyz>
                <limit>
                    <lower>-1e+16</lower>
                    <upper>1e+16</upper>
                </limit>
                <dynamics>
                    <spring_reference>0</spring_reference>
                    <spring_stiffness>0</spring_stiffness>
                </dynamics>
                <use_parent_model_frame>1</use_parent_model_frame>
            </axis>
        </joint>
        <link name="rotor_1">
            <pose frame="">-0.09 0.09 0.045 0 -0 0</pose>
            <inertial>
                <pose frame="">0 0 0 0 -0 0</pose>
                <mass>0.005</mass>
                <inertia>
                    <ixx>9.75e-07</ixx>
                    <ixy>0</ixy>
                    <ixz>0</ixz>
                    <iyy>8.13545e-05</iyy>
                    <iyz>0</iyz>
                    <izz>8.22545e-05</izz>
                </inertia>
            </inertial>
            <collision name="rotor_1_collision">
                <pose frame="">0 0 0 0 -0 0</pose>
                <geometry>
                    <cylinder>
                        <length>0.005</length>
                        <radius>0.06</radius>
                    </cylinder>
                </geometry>
                <surface>
                    <contact>
                        <ode />
                    </contact>
                    <friction>
                        <ode />
                    </friction>
                </surface>
            </collision>
            <visual name="rotor_1_visual">
                <pose frame="">0 0 0 0 -0 0</pose>
                <geometry>
                    <mesh>
                        <scale>1 1 1</scale>
                        <uri>meshes/propeller_ccw.dae</uri>
                    </mesh>
                </geometry>
                <material>
                    <diffuse>0 0 1 1</diffuse>
                    <script>
                        <name>Gazebo/Blue</name>
                        <uri>file://media/materials/scripts/gazebo.material</uri>
                    </script>
                </material>
                <cast_shadows>0</cast_shadows>
            </visual>
            <gravity>1</gravity>
            <velocity_decay/>
        </link>
        <joint name="rotor_1_joint" type="revolute">
            <child>rotor_1</child>
            <parent>base_link</parent>
            <axis>
                <xyz>0 0 1</xyz>
                <limit>
                    <lower>-1e+16</lower>
                    <upper>1e+16</upper>
                </limit>
                <dynamics>
                    <spring_reference>0</spring_reference>
                    <spring_stiffness>0</spring_stiffness>
                </dynamics>
                <use_parent_model_frame>1</use_parent_model_frame>
            </axis>
        </joint>
        <link name="rotor_2">
            <pose frame="">0.09 0.09 -0.005 0 0 0</pose>
            <inertial>
                <pose frame="">0 0 0 0 -0 0</pose>
                <mass>0.005</mass>
                <inertia>
                    <ixx>9.75e-07</ixx>
                    <ixy>0</ixy>
                    <ixz>0</ixz>
                    <iyy>8.13545e-05</iyy>
                    <iyz>0</iyz>
                    <izz>8.22545e-05</izz>
                </inertia>
            </inertial>
            <collision name="rotor_2_collision">
                <pose frame="">0 0 0 0 -0 0</pose>
                <geometry>
                    <cylinder>
                        <length>0.005</length>
                        <radius>0.06</radius>
                    </cylinder>
                </geometry>
                <surface>
                    <contact>
                        <ode />
                    </contact>
                    <friction>
                        <ode />
                    </friction>
                </surface>
            </collision>
            <visual name="rotor_2_visual">
                <pose frame="">0 0 0 0 -0 0</pose>
                <geometry>
                    <mesh>
                        <scale>1 1 1</scale>
                        <uri>meshes/propeller_cw.dae</uri>
                    </mesh>
                </geometry>
                <material>
                    <diffuse>1 0 0 1</diffuse>
                    <script>
                        <name>Gazebo/Red</name>
                        <uri>file://media/materials/scripts/gazebo.material</uri>
                    </script>
                </material>
                <cast_shadows>0</cast_shadows>
            </visual>
            <gravity>1</gravity>
            <velocity_decay/>
        </link>
        <joint name="rotor_2_joint" type="revolute">
            <child>rotor_2</child>
            <parent>base_link</parent>
            <axis>
                <xyz>0 0 1</xyz>
                <limit>
                    <lower>-1e+16</lower>
                    <upper>1e+16</upper>
                </limit>
                <dynamics>
                    <spring_reference>0</spring_reference>
                    <spring_stiffness>0</spring_stiffness>
                </dynamics>
                <use_parent_model_frame>1</use_parent_model_frame>
            </axis>
        </joint>
        <link name="rotor_3">
            <pose frame="">-0.09 -0.09 0.045 0 -0 0</pose>
            <inertial>
                <pose frame="">0 0 0 0 -0 0</pose>
                <mass>0.005</mass>
                <inertia>
                    <ixx>9.75e-07</ixx>
                    <ixy>0</ixy>
                    <ixz>0</ixz>
                    <iyy>8.13545e-05</iyy>
                    <iyz>0</iyz>
                    <izz>8.22545e-05</izz>
                </inertia>
            </inertial>
            <collision name="rotor_3_collision">
                <pose frame="">0 0 0 0 -0 0</pose>
                <geometry>
                    <cylinder>
                        <length>0.005</length>
                        <radius>0.06</radius>
                    </cylinder>
                </geometry>
                <surface>
                    <contact>
                        <ode />
                    </contact>
                    <friction>
                        <ode />
                    </friction>
                </surface>
            </collision>
            <visual name="rotor_3_visual">
                <pose frame="">0 0 0 0 -0 0</pose>
                <geometry>
                    <mesh>
                        <scale>1 1 1</scale>
                        <uri>meshes/propeller_cw.dae</uri>
                    </mesh>
                </geometry>
                <material>
                    <diffuse>0 0 1 1</diffuse>
                    <script>
                        <name>Gazebo/Blue</name>
                        <uri>file://media/materials/scripts/gazebo.material</uri>
                    </script>
                </material>
                <cast_shadows>0</cast_shadows>
            </visual>
            <gravity>1</gravity>
            <velocity_decay/>
        </link>
        <joint name="rotor_3_joint" type="revolute">
            <child>rotor_3</child>
            <parent>base_link</parent>
            <axis>
                <xyz>0 0 1</xyz>
                <limit>
                    <lower>-1e+16</lower>
                    <upper>1e+16</upper>
                </limit>
                <dynamics>
                    <spring_reference>0</spring_reference>
                    <spring_stiffness>0</spring_stiffness>
                </dynamics>
                <use_parent_model_frame>1</use_parent_model_frame>
            </axis>
        </joint>

        <!-- Plugins -->
        <plugin filename="gz-sim-multicopter-motor-model-system"
            name="gz::sim::systems::MulticopterMotorModel">
            <robotNamespace>rmf_owl</robotNamespace>
            <jointName>rotor_0_joint</jointName>
            <linkName>rotor_0</linkName>
            <turningDirection>ccw</turningDirection>
            <timeConstantUp>0.0125</timeConstantUp>
            <timeConstantDown>0.025</timeConstantDown>
            <maxRotVelocity>2000.0</maxRotVelocity>
            <motorConstant>8.54858e-06</motorConstant>
            <momentConstant>0.016</momentConstant>
            <commandSubTopic>gazebo/command/motor_speed</commandSubTopic>
            <motorNumber>0</motorNumber>
            <rotorDragCoefficient>8.06428e-05</rotorDragCoefficient>
            <rollingMomentCoefficient>1e-06</rollingMomentCoefficient>
            <motorSpeedPubTopic>motor_speed/0</motorSpeedPubTopic>
            <rotorVelocitySlowdownSim>10</rotorVelocitySlowdownSim>
            <motorType>velocity</motorType>
        </plugin>
        <plugin filename="gz-sim-multicopter-motor-model-system"
            name="gz::sim::systems::MulticopterMotorModel">
            <robotNamespace>rmf_owl</robotNamespace>
            <jointName>rotor_2_joint</jointName>
            <linkName>rotor_2</linkName>
            <turningDirection>cw</turningDirection>
            <timeConstantUp>0.0125</timeConstantUp>
            <timeConstantDown>0.025</timeConstantDown>
            <maxRotVelocity>2000.0</maxRotVelocity>
            <motorConstant>8.54858e-06</motorConstant>
            <momentConstant>0.016</momentConstant>
            <commandSubTopic>gazebo/command/motor_speed</commandSubTopic>
            <motorNumber>2</motorNumber>
            <rotorDragCoefficient>8.06428e-05</rotorDragCoefficient>
            <rollingMomentCoefficient>1e-06</rollingMomentCoefficient>
            <motorSpeedPubTopic>motor_speed/2</motorSpeedPubTopic>
            <rotorVelocitySlowdownSim>10</rotorVelocitySlowdownSim>
            <motorType>velocity</motorType>
        </plugin>
        <plugin filename="gz-sim-multicopter-motor-model-system"
            name="gz::sim::systems::MulticopterMotorModel">
            <robotNamespace>rmf_owl</robotNamespace>
            <jointName>rotor_1_joint</jointName>
            <linkName>rotor_1</linkName>
            <turningDirection>ccw</turningDirection>
            <timeConstantUp>0.0125</timeConstantUp>
            <timeConstantDown>0.025</timeConstantDown>
            <maxRotVelocity>2000.0</maxRotVelocity>
            <motorConstant>8.54858e-06</motorConstant>
            <momentConstant>0.016</momentConstant>
            <commandSubTopic>gazebo/command/motor_speed</commandSubTopic>
            <motorNumber>1</motorNumber>
            <rotorDragCoefficient>8.06428e-05</rotorDragCoefficient>
            <rollingMomentCoefficient>1e-06</rollingMomentCoefficient>
            <motorSpeedPubTopic>motor_speed/1</motorSpeedPubTopic>
            <rotorVelocitySlowdownSim>10</rotorVelocitySlowdownSim>
            <motorType>velocity</motorType>
        </plugin>
        <plugin filename="gz-sim-multicopter-motor-model-system"
            name="gz::sim::systems::MulticopterMotorModel">
            <robotNamespace>rmf_owl</robotNamespace>
            <jointName>rotor_3_joint</jointName>
            <linkName>rotor_3</linkName>
            <turningDirection>cw</turningDirection>
            <timeConstantUp>0.0125</timeConstantUp>
            <timeConstantDown>0.025</timeConstantDown>
            <maxRotVelocity>2000.0</maxRotVelocity>
            <motorConstant>8.54858e-06</motorConstant>
            <momentConstant>0.016</momentConstant>
            <commandSubTopic>gazebo/command/motor_speed</commandSubTopic>
            <motorNumber>3</motorNumber>
            <rotorDragCoefficient>8.06428e-05</rotorDragCoefficient>
            <rollingMomentCoefficient>1e-06</rollingMomentCoefficient>
            <motorSpeedPubTopic>motor_speed/3</motorSpeedPubTopic>
            <rotorVelocitySlowdownSim>10</rotorVelocitySlowdownSim>
            <motorType>velocity</motorType>
        </plugin>
        <plugin filename="gz-sim-multicopter-control-system"
            name="gz::sim::systems::MulticopterVelocityControl">
            <robotNamespace>rmf_owl</robotNamespace>
            <commandSubTopic>command/velocity</commandSubTopic>
            <enableSubTopic>enable</enableSubTopic>
            <comLinkName>base_link</comLinkName>
            <velocityGain>2.7 2.7 2.7</velocityGain>
            <attitudeGain>2 3 0.15</attitudeGain>
            <angularRateGain>0.4 0.52 0.18</angularRateGain>
            <maximumLinearAcceleration>2 2 2</maximumLinearAcceleration>

            <rotorConfiguration>
            <rotor>
                <jointName>rotor_0_joint</jointName>
                <forceConstant>8.54858e-06</forceConstant>
                <momentConstant>0.016</momentConstant>
                <direction>1</direction>
            </rotor>
            <rotor>
                <jointName>rotor_1_joint</jointName>
                <forceConstant>8.54858e-06</forceConstant>
                <momentConstant>0.016</momentConstant>
                <direction>1</direction>
            </rotor>
            <rotor>
                <jointName>rotor_2_joint</jointName>
                <forceConstant>8.54858e-06</forceConstant>
                <momentConstant>0.016</momentConstant>
                <direction>-1</direction>
            </rotor>
            <rotor>
                <jointName>rotor_3_joint</jointName>
                <forceConstant>8.54858e-06</forceConstant>
                <momentConstant>0.016</momentConstant>
                <direction>-1</direction>
            </rotor>
            </rotorConfiguration>
        </plugin>
        <plugin filename="gz-sim-multicopter-position-control-system"
            name="gz::sim::systems::MulticopterPositionControl">
            <robotNamespace>rmf_owl</robotNamespace>
            <commandSubTopic>command/pose</commandSubTopic>
            <enableSubTopic>enable</enableSubTopic>
            <comLinkName>base_link</comLinkName>
            <positionGain>6 6 6</positionGain>
            <velocityGain>5.0 5.0 5.0</velocityGain>
            <attitudeGain>3 3 1.2</attitudeGain>
            <angularRateGain>0.52 0.52 0.1</angularRateGain>
            <maximumLinearAcceleration>2 2 2</maximumLinearAcceleration>

            <rotorConfiguration>
            <rotor>
                <jointName>rotor_0_joint</jointName>
                <forceConstant>8.54858e-06</forceConstant>
                <momentConstant>0.016</momentConstant>
                <direction>1</direction>
            </rotor>
            <rotor>
                <jointName>rotor_1_joint</jointName>
                <forceConstant>8.54858e-06</forceConstant>
                <momentConstant>0.016</momentConstant>
                <direction>1</direction>
            </rotor>
            <rotor>
                <jointName>rotor_2_joint</jointName>
                <forceConstant>8.54858e-06</forceConstant>
                <momentConstant>0.016</momentConstant>
                <direction>-1</direction>
            </rotor>
            <rotor>
                <jointName>rotor_3_joint</jointName>
                <forceConstant>8.54858e-06</forceConstant>
                <momentConstant>0.016</momentConstant>
                <direction>-1</direction>
            </rotor>
            </rotorConfiguration>
        </plugin>
        <plugin filename="gz-sim-odometry-publisher-system"
            name="gz::sim::systems::OdometryPublisher">
            <odom_frame>world</odom_frame>
            <robot_base_frame>rmf_owl</robot_base_frame>
            <odom_publish_frequency>50</odom_publish_frequency>
            <odom_topic>rmf_owl/odometry</odom_topic>
            <odom_covariance_topic>rmf_owl/odometry_with_covariance</odom_covariance_topic>
            <!-- <tf_topic>rmf_owl/pose</tf_topic> -->
            <dimensions>3</dimensions>
        </plugin>
        <plugin filename="gz-sim-pose-publisher-system"
            name="gz::sim::systems::PosePublisher">
            <publish_link_pose>true</publish_link_pose>
            <publish_visual_pose>true</publish_visual_pose>
            <publish_collision_pose>true</publish_collision_pose>
            <publish_sensor_pose>true</publish_sensor_pose>
            <publish_model_pose>true</publish_model_pose>
            <publish_nested_model_pose>false</publish_nested_model_pose>
            <use_pose_vector_msg>true</use_pose_vector_msg>
            <static_publisher>true</static_publisher> 
            <static_update_frequency>200</static_update_frequency> 
        </plugin>
        <plugin filename="gz-sim-linearbatteryplugin-system"
            name="gz::sim::systems::LinearBatteryPlugin">
            <!--Li-ion battery spec from LIR18650 datasheet-->
            <battery_name>linear_battery</battery_name>
            <voltage>22.2</voltage>
            <open_circuit_voltage_constant_coef>22.2</open_circuit_voltage_constant_coef>
            <open_circuit_voltage_linear_coef>-3.1424</open_circuit_voltage_linear_coef>
            <initial_charge>90.0</initial_charge>
            <capacity>90.0</capacity>
            <resistance>0.061523</resistance>
            <smooth_current_tau>1.9499</smooth_current_tau>
            <enable_recharge>false</enable_recharge>
            <power_load>0.8</power_load>
            <start_on_motion>true</start_on_motion>
        </plugin>
        <!-- <plugin filename="gz-sim-joint-state-publisher-system"
            name="gz::sim::systems::JointStatePublisher">
            <topic>rmf_owl/joint_state</topic>
        </plugin> -->
        <plugin filename="gz-sim-joint-position-controller-system"
                name="gz::sim::systems::JointPositionController">
            <joint_name>camera_joint_pitch</joint_name>
            <topic>rotatable_camera_pitch</topic>
            <p_gain>0.1</p_gain>
            <i_gain>0.1</i_gain>
            <d_gain>0.05</d_gain>
            <i_max>1</i_max>
            <i_min>-1</i_min>
            <cmd_max>10</cmd_max>
            <cmd_min>-10</cmd_min>
        </plugin>

        <plugin filename="gz-sim-joint-state-publisher-system"
                name="gz::sim::systems::JointStatePublisher">
            <joint_name>camera_joint_pitch</joint_name>
            <topic>rotatable_camera_pitch_state</topic>
        </plugin>
    </model>
</sdf>

<!--
  Multicopter velocity controller demo

You can use the velocity controller and command linear velocity and yaw angular velocity in the body frame of the vehicle

  Send commands to the quadcopter to go straight up:

    gz topic -t "/rmf_owl/cmd_vel" -m gz.msgs.Twist -p "linear: {x:0 y: 0 z: 0.1} angular {z: 0}"

  To hover

    gz topic -t "/rmf_owl/cmd_vel" -m gz.msgs.Twist -p " "

  Listen to odometry:

    gz topic -e -t "/model/rmf_owl/odometry"

  Listen to poses:

    gz topic -e -t "/model/x3/pose"


  Send commands to the hexacopter to go straight up:

    gz topic -t "/X4/gazebo/command/twist" -m gz.msgs.Twist -p "linear: {x:0 y: 0 z: 0.1} angular {z: 0}"

  To hover

    gz topic -t "/X4/gazebo/command/twist" -m gz.msgs.Twist -p " "

  Listen to odometry:

    gz topic -e -t "/model/X4/odometry"

-->

