<?xml version='1.0' encoding='utf-8'?>
<sdf version="1.6">
  <model name="marble_husky" canonical_link="base_link">
    <link name="base_link">
      <pose frame="">0 0 0 0 -0 0</pose>
      
      <inertial>
        <pose frame="">-0.000543 -0.084945 0.062329 0 -0 0</pose>
        <mass>46.064</mass>
        <inertia>
          <ixx>0.615397</ixx>
          <ixy>-0.0240585</ixy>
          <ixz>-0.120749</ixz>
          <iyy>1.75388</iyy>
          <iyz>-0.0028322</iyz>
          <izz>2.03641</izz>
        </inertia>
      </inertial>

      <collision name="base_link_collision">
        <pose frame="">0 0 0.12 0 0 0</pose>
        <geometry>
          <box>
            <size>0.9874 0.5709 0.05</size>
          </box>
        </geometry>
      </collision>
      <collision name="base_link_collision_bottom">
        <pose frame="">0 0 0.046 0 0 0</pose>
        <geometry>
          <box>
            <size>0.80 0.5709 0.095</size>
          </box>
        </geometry>
      </collision>
      <collision name="base_link_collision_1">
        <pose frame="">0 0 0.185625 0 -0 0</pose>
        <geometry>
          <box>
            <size>0.78992 0.5709 0.12375</size>
          </box>
        </geometry>
      </collision>
      <collision name="base_link_fixed_joint_lump__camera/camera_link_collision_2">
        <pose frame="">0.478 0 0.285 0 -0 0</pose>
        <geometry>
          <box>
            <size>0.0078 0.13 0.0192</size>
          </box>
        </geometry>
        <surface>
          <contact>
            <ode>
              <kp>1e+13</kp>
              <kd>1</kd>
            </ode>
          </contact>
          <friction>
            <ode>
              <mu2>1</mu2>
              <fdir1>0 0 0</fdir1>
            </ode>
          </friction>
        </surface>
      </collision>
      <collision name="base_link_fixed_joint_lump__camera/camera_link_collision_3">
        <pose frame="">0.473 0 0.260 0 0.5236 0</pose>
        <geometry>
          <box>
            <size>0.0078 0.13 0.0192</size>
          </box>
        </geometry>
        <surface>
          <contact>
            <ode>
              <kp>1e+13</kp>
              <kd>1</kd>
            </ode>
          </contact>
          <friction>
            <ode>
              <mu2>1</mu2>
              <fdir1>0 0 0</fdir1>
            </ode>
          </friction>
        </surface>
      </collision>
      <collision name="base_link_fixed_joint_lump__velodyne_base_link_collision_6">
        <pose frame="">0.424 0 0.327 0 -0 0</pose>
        <geometry>
          <cylinder>
            <length>0.0717</length>
            <radius>0.0516</radius>
          </cylinder>
        </geometry>
      </collision>
      <collision name="base_link_fixed_joint_lump__velodyne_gimbal_plate_base_link_collision_7">
        <pose frame="">0.424 0 0.400 0 -0 0</pose>
        <geometry>
          <box>
            <size>0.1 0.1 0.01</size>
          </box>
        </geometry>
      </collision>
      <collision name="base_link_fixed_joint_lump__sensor_tower_8">
       <pose frame="">0.374 0 0.215 0 -0 0</pose>
        <geometry>
          <box>
            <size>0.2 0.25 0.225</size>
          </box>
        </geometry>
      </collision>
      <collision name="base_link_fixed_joint_lump__computer_block_9">
       <pose frame="">0.050 0 0.185 0 -0 0</pose>
        <geometry>
          <box>
            <size>0.30 0.355 0.175</size>
          </box>
        </geometry>
      </collision>

      <visual name="base_link_visual">
        <pose frame="">0 0 0 0 -0 0</pose>
        <geometry>
          <mesh>
            <scale>1 1 1</scale>
            <uri>meshes/base_link.dae</uri>
          </mesh>
        </geometry>
      </visual>
      <visual name="base_link_fixed_joint_lump__camera/camera_link_visual_2">
        <pose frame="">0.478 0 0.285 0 -0 0</pose>
        <geometry>
          <mesh>
            <uri>meshes/realsense.dae</uri>
          </mesh>
        </geometry>
      </visual>
      <visual name="base_link_fixed_joint_lump__front_bumper_link_visual_3">
        <pose frame="">0.48 0 0.091 0 -0 0</pose>
        <geometry>
          <mesh>
            <scale>1 1 1</scale>
            <uri>meshes/bumper.dae</uri>
          </mesh>
        </geometry>
      </visual>
      <visual name="base_link_fixed_joint_lump__rear_bumper_link_visual_4">
        <pose frame="">-0.48 0 0.091 0 -0 3.14159</pose>
        <geometry>
          <mesh>
            <scale>1 1 1</scale>
            <uri>meshes/bumper.dae</uri>
          </mesh>
        </geometry>
      </visual>
      <visual name="base_link_fixed_joint_lump__top_chassis_link_visual_5">
        <pose frame="">0 0 0 0 -0 0</pose>
        <geometry>
          <mesh>
            <scale>1 1 1</scale>
            <uri>meshes/top_chassis.dae</uri>
          </mesh>
        </geometry>
      </visual>
      <!-- Bottom cylinder of Ouster/Velodyne 3D Lidar -->
      <visual name="base_link_fixed_joint_lump__velodyne_base_link_visual_10">
        <pose frame="">0.424 0 0.327 0 -0 0</pose>
        <geometry>
          <mesh>
            <scale>1 1 1</scale>
            <uri>meshes/VLP16_base_1.dae</uri>
          </mesh>
        </geometry>
      </visual>
      <!-- Top cylinder of Ouster/Velodyne 3D Lidar -->
      <visual name="base_link_fixed_joint_lump__velodyne_base_link_visual_11">
        <pose frame="">0.424 0 0.327 0 -0 0</pose>
        <geometry>
          <mesh>
            <scale>1 1 1</scale>
            <uri>meshes/VLP16_base_2.dae</uri>
          </mesh>
        </geometry>
      </visual>
      <!-- Main cylinder of Ouster/Velodyne 3D Lidar -->
      <visual name="base_link_fixed_joint_lump__velodyne_visual_12">
        <pose frame="">0.424 0 0.327 0 -0 0</pose>
        <geometry>
          <mesh>
            <scale>1 1 1</scale>
            <uri>meshes/VLP16_scan.dae</uri>
          </mesh>
        </geometry>
      </visual>
      <!-- <visual name="base_link_fixed_joint_lump__velodyne_gimbal_plate_15">
       <pose frame="">0.424 0 0.400 0 -0 0</pose>
        <geometry>
          <box>
            <size>0.06 0.06 0.01</size>
          </box>
        </geometry>
      </visual> -->
      <visual name="base_link_fixed_joint_lump__sensor_tower_16">
       <pose frame="">0.374 0 0.215 0 -0 0</pose>
        <geometry>
          <box>
            <size>0.2 0.25 0.225</size>
          </box>
        </geometry>
      </visual>
      <visual name="base_link_fixed_joint_lump__computer_block_17">
       <pose frame="">0.050 0 0.185 0 -0 0</pose>
        <geometry>
          <box>
            <!-- 0.30 0.355 0.175 -->
            <size>0.29 0.415 0.078</size>
          </box>
        </geometry>
      </visual>

      <!-- Based on Intel realsense D435 (intrinsics and distortion not modeled)-->
      <sensor name="camera_front" type="rgbd_camera">
        <camera name="camera_front">
            <horizontal_fov>1.5184</horizontal_fov>
            <lens>
                <intrinsics>
                    <!-- fx = fy = width / ( 2 * tan (hfov / 2 ) ) -->
                    <fx>168.61097</fx>
                    <fy>168.61097</fy>
                    <!-- cx = ( width + 1 ) / 2 -->
                    <cx>160.5</cx>
                    <!-- cy = ( height + 1 ) / 2 -->
                    <cy>120.5</cy>
                    <s>0</s>
                </intrinsics>
            </lens>
            <distortion>
                <k1>0.0</k1>
                <k2>0.0</k2>
                <k3>0.0</k3>
                <p1>0.0</p1>
                <p2>0.0</p2>
                <center>0.5 0.5</center>
            </distortion>
            <image>
                <width>320</width>
                <height>240</height>
                <format>R8G8B8</format>
            </image>
            <clip>
                <near>0.01</near>
                <far>300</far>
            </clip>
            <depth_camera>
              <clip>
                <near>0.1</near>
                <far>10</far>
              </clip>
            </depth_camera>
            <noise>
                <type>gaussian</type>
                <mean>0</mean>
                <stddev>0.007</stddev>
            </noise>
        </camera>
        <always_on>1</always_on>
        <update_rate>30</update_rate>
        <visualize>1</visualize>
        <pose frame="">0.468 0 0.360 0 -0 0</pose>
      </sensor>
      <!-- OS1-128 3D Laser Configuration (10x2048 or 10x1024 or 20x1024 or 20x512 as possible (rate) x (hor. res.) configs)-->
      <sensor name="laser" type="gpu_lidar">
        <pose frame="">0.424 0 0.387 0 -0 0</pose>
        <topic>marble_husky/lidar</topic>
        <visualize>1</visualize>
        <update_rate>10</update_rate>
        <always_on>1</always_on>
        <lidar>
          <scan>
            <horizontal>
              <samples>2048</samples>
              <resolution>1</resolution>
              <min_angle>-3.14159</min_angle>
              <max_angle>3.14159</max_angle>
            </horizontal>
            <vertical>
              <samples>128</samples>
              <resolution>1</resolution>
              <min_angle>-0.2897</min_angle>
              <max_angle>0.2897</max_angle>
            </vertical>
          </scan>
          <range>
            <min>0.8</min>
            <max>120</max>
            <resolution>0.01</resolution>
          </range>
          <noise>
            <type>gaussian</type>
            <mean>0</mean>
            <stddev>0.01</stddev>
          </noise>
        </lidar>
      </sensor>
      <!-- IMU -->
      <sensor name="imu_sensor" type="imu">
        <always_on>1</always_on>
        <update_rate>200</update_rate>
        <visualize>true</visualize>
        <topic>marble_husky/imu</topic>
        <imu>
            <enable_orientation>0</enable_orientation>
            <angular_velocity>
                <x>
                    <noise type="gaussian">
                        <mean>0</mean>
                        <stddev>0.009</stddev>
                        <bias_mean>0.00075</bias_mean>
                        <bias_stddev>0.005</bias_stddev>
                        <dynamic_bias_stddev>0.00002</dynamic_bias_stddev>
                        <dynamic_bias_correlation_time>400.0</dynamic_bias_correlation_time>
                        <precision>0.00025</precision>
                    </noise>
                </x>
                <y>
                    <noise type="gaussian">
                        <mean>0</mean>
                        <stddev>0.009</stddev>
                        <bias_mean>0.00075</bias_mean>
                        <bias_stddev>0.005</bias_stddev>
                        <dynamic_bias_stddev>0.00002</dynamic_bias_stddev>
                        <dynamic_bias_correlation_time>400.0</dynamic_bias_correlation_time>
                        <precision>0.00025</precision>
                    </noise>
                </y>
                <z>
                    <noise type="gaussian">
                        <mean>0</mean>
                        <stddev>0.009</stddev>
                        <bias_mean>0.00075</bias_mean>
                        <bias_stddev>0.005</bias_stddev>
                        <dynamic_bias_stddev>0.00002</dynamic_bias_stddev>
                        <dynamic_bias_correlation_time>400.0</dynamic_bias_correlation_time>
                        <precision>0.00025</precision>
                    </noise>
                </z>
            </angular_velocity>
            <linear_acceleration>
                <x>
                    <noise type="gaussian">
                        <mean>0</mean>
                        <stddev>0.021</stddev>
                        <bias_mean>0.05</bias_mean>
                        <bias_stddev>0.0075</bias_stddev>
                        <dynamic_bias_stddev>0.000375</dynamic_bias_stddev>
                        <dynamic_bias_correlation_time>175.0</dynamic_bias_correlation_time>
                        <precision>0.005</precision>
                    </noise>
                </x>
                <y>
                    <noise type="gaussian">
                        <mean>0</mean>
                        <stddev>0.021</stddev>
                        <bias_mean>0.05</bias_mean>
                        <bias_stddev>0.0075</bias_stddev>
                        <dynamic_bias_stddev>0.000375</dynamic_bias_stddev>
                        <dynamic_bias_correlation_time>175.0</dynamic_bias_correlation_time>
                        <precision>0.005</precision>
                    </noise>
                </y>
                <z>
                    <noise type="gaussian">
                        <mean>0</mean>
                        <stddev>0.021</stddev>
                        <bias_mean>0.05</bias_mean>
                        <bias_stddev>0.0075</bias_stddev>
                        <dynamic_bias_stddev>0.000375</dynamic_bias_stddev>
                        <dynamic_bias_correlation_time>175.0</dynamic_bias_correlation_time>
                        <precision>0.005</precision>
                    </noise>
                </z>
            </linear_acceleration>
        </imu>
      </sensor>
      <!-- <sensor name="air_pressure" type="air_pressure"> 
        <always_on>1</always_on> 
        <update_rate>20</update_rate> 
        <air_pressure> 
            <reference_altitude>0</reference_altitude> 
            <noise type="gaussian">
                <mean>0.00000008</mean>
            </noise>
        </air_pressure>
      </sensor>
      <sensor name="magnetometer" type="magnetometer">
        <always_on>1</always_on>
        <update_rate>20</update_rate>
        <magnetometer>
            <x>
                <noise type="gaussian">
                    <mean>0.000000080</mean>
                    <bias_mean>0.000000400</bias_mean>
                </noise>
            </x>
            <y>
                <noise type="gaussian">
                    <mean>0.000000080</mean>
                    <bias_mean>0.000000400</bias_mean>
                </noise>
            </y>
            <z>
                <noise type="gaussian">
                    <mean>0.000000080</mean>
                    <bias_mean>0.000000400</bias_mean>
                </noise>
            </z>
        </magnetometer>
      </sensor> -->

      <gravity>1</gravity>
      <velocity_decay/>
      <!-- <self_collide>0</self_collide> -->
      <!-- <enable_wind>0</enable_wind> -->
      <!-- <kinematic>0</kinematic> -->

    </link>
    <link name="front_left_wheel_link">
      <pose frame="">0.256 0.2854 0.03282 0 -0 0</pose>
      <inertial>
        <pose frame="">0 0 0 0 -0 0</pose>
        <mass>2.637</mass>
        <inertia>
          <ixx>0.02467</ixx>
          <ixy>0</ixy>
          <ixz>0</ixz>
          <iyy>0.04411</iyy>
          <iyz>0</iyz>
          <izz>0.02467</izz>
        </inertia>
      </inertial>
      <collision name="front_left_wheel_link_collision">
        <pose frame="">0 0 0 1.5707963267948966 -0 0</pose>
        <geometry>
          <cylinder>
            <length>0.1143</length>
            <radius>0.1651</radius>
          </cylinder>
        </geometry>
        <surface>
          <contact>
            <ode>
              <kp>1e+07</kp>
              <kd>1</kd>
            </ode>
          </contact>
          <friction>
            <ode>
              <mu>10.5</mu>
              <mu2>20</mu2>
              <slip1>0.00062</slip1>
              <slip2>0</slip2>
              <fdir1>0 0 1</fdir1>
            </ode>
          </friction>
        </surface>
      </collision>
      <visual name="front_left_wheel_link_visual">
        <pose frame="">0 0 0 0 -0 0</pose>
        <geometry>
          <mesh>
            <scale>1 1 1</scale>
            <uri>meshes/wheel.dae</uri>
          </mesh>
        </geometry>
      </visual>
      <gravity>1</gravity>
      <velocity_decay/>
    </link>
    <joint name="front_left_wheel_joint" type="revolute">
      <child>front_left_wheel_link</child>
      <parent>base_link</parent>
      <axis>
        <xyz>0 1 0</xyz>
        <limit>
          <lower>-1e+16</lower>
          <upper>1e+16</upper>
        </limit>
        <dynamics>
          <spring_reference>0</spring_reference>
          <spring_stiffness>0</spring_stiffness>
        </dynamics>
        <use_parent_model_frame>1</use_parent_model_frame>
      </axis>
    </joint>
    <link name="front_right_wheel_link">
      <pose frame="">0.256 -0.2854 0.03282 0 -0 0</pose>
      <inertial>
        <pose frame="">0 0 0 0 -0 0</pose>
        <mass>2.637</mass>
        <inertia>
          <ixx>0.02467</ixx>
          <ixy>0</ixy>
          <ixz>0</ixz>
          <iyy>0.04411</iyy>
          <iyz>0</iyz>
          <izz>0.02467</izz>
        </inertia>
      </inertial>
      <collision name="front_right_wheel_link_collision">
        <pose frame="">0 0 0 1.5707963267948966 -0 0</pose>
        <geometry>
          <cylinder>
            <length>0.1143</length>
            <radius>0.1651</radius>
          </cylinder>
        </geometry>
        <surface>
          <contact>
            <ode>
              <kp>1e+07</kp>
              <kd>1</kd>
            </ode>
          </contact>
          <friction>
            <ode>
              <mu>10.5</mu>
              <mu2>20</mu2>
              <slip1>0.00062</slip1>
              <slip2>0</slip2>
              <fdir1>0 0 1</fdir1>
            </ode>
          </friction>
        </surface>
      </collision>
      <visual name="front_right_wheel_link_visual">
        <pose frame="">0 0 0 0 -0 0</pose>
        <geometry>
          <mesh>
            <scale>1 1 1</scale>
            <uri>meshes/wheel.dae</uri>
          </mesh>
        </geometry>
      </visual>
      <gravity>1</gravity>
      <velocity_decay/>
    </link>
    <joint name="front_right_wheel_joint" type="revolute">
      <child>front_right_wheel_link</child>
      <parent>base_link</parent>
      <axis>
        <xyz>0 1 0</xyz>
        <limit>
          <lower>-1e+16</lower>
          <upper>1e+16</upper>
        </limit>
        <dynamics>
          <spring_reference>0</spring_reference>
          <spring_stiffness>0</spring_stiffness>
        </dynamics>
        <use_parent_model_frame>1</use_parent_model_frame>
      </axis>
    </joint>
    <link name="rear_left_wheel_link">
      <pose frame="">-0.256 0.2854 0.03282 0 -0 0</pose>
      <inertial>
        <pose frame="">0 0 0 0 -0 0</pose>
        <mass>2.637</mass>
        <inertia>
          <ixx>0.02467</ixx>
          <ixy>0</ixy>
          <ixz>0</ixz>
          <iyy>0.04411</iyy>
          <iyz>0</iyz>
          <izz>0.02467</izz>
        </inertia>
      </inertial>
      <collision name="rear_left_wheel_link_collision">
        <pose frame="">0 0 0 1.5707963267948966 -0 0</pose>
        <geometry>
          <cylinder>
            <length>0.1143</length>
            <radius>0.1651</radius>
          </cylinder>
        </geometry>
        <surface>
          <contact>
            <ode>
              <kp>1e+07</kp>
              <kd>1</kd>
            </ode>
          </contact>
          <friction>
            <ode>
              <mu>10.5</mu>
              <mu2>20</mu2>
              <slip1>0.00062</slip1>
              <slip2>0</slip2>
              <fdir1>0 0 1</fdir1>
            </ode>
          </friction>
        </surface>
      </collision>
      <visual name="rear_left_wheel_link_visual">
        <pose frame="">0 0 0 0 0 0</pose>
        <geometry>
          <mesh>
            <scale>1 1 1</scale>
            <uri>meshes/wheel.dae</uri>
          </mesh>
        </geometry>
      </visual>
      <gravity>1</gravity>
      <velocity_decay/>
    </link>
    <joint name="rear_left_wheel_joint" type="revolute">
      <child>rear_left_wheel_link</child>
      <parent>base_link</parent>
      <axis>
        <xyz>0 1 0</xyz>
        <limit>
          <lower>-1e+16</lower>
          <upper>1e+16</upper>
        </limit>
        <dynamics>
          <spring_reference>0</spring_reference>
          <spring_stiffness>0</spring_stiffness>
        </dynamics>
        <use_parent_model_frame>1</use_parent_model_frame>
      </axis>
    </joint>
    <link name="rear_right_wheel_link">
      <pose frame="">-0.256 -0.2854 0.03282 0 -0 0</pose>
      <inertial>
        <pose frame="">0 0 0 0 -0 0</pose>
        <mass>2.637</mass>
        <inertia>
          <ixx>0.02467</ixx>
          <ixy>0</ixy>
          <ixz>0</ixz>
          <iyy>0.04411</iyy>
          <iyz>0</iyz>
          <izz>0.02467</izz>
        </inertia>
      </inertial>
      <collision name="rear_right_wheel_link_collision">
        <pose frame="">0 0 0 1.5707963267948966 -0 0</pose>
        <geometry>
          <cylinder>
            <length>0.1143</length>
            <radius>0.1651</radius>
          </cylinder>
        </geometry>
        <surface>
          <contact>
            <ode>
              <kp>1e+07</kp>
              <kd>1</kd>
            </ode>
          </contact>
          <friction>
            <ode>
              <mu>10.5</mu>
              <mu2>20</mu2>
              <slip1>0.00062</slip1>
              <slip2>0</slip2>
              <fdir1>0 0 1</fdir1>
            </ode>
          </friction>
        </surface>
      </collision>
      <visual name="rear_right_wheel_link_visual">
        <pose frame="">0 0 0 0 -0 0</pose>
        <geometry>
          <mesh>
            <scale>1 1 1</scale>
            <uri>meshes/wheel.dae</uri>
          </mesh>
        </geometry>
      </visual>
      <gravity>1</gravity>
      <velocity_decay/>
    </link>
    <joint name="rear_right_wheel_joint" type="revolute">
      <child>rear_right_wheel_link</child>
      <parent>base_link</parent>
      <axis>
        <xyz>0 1 0</xyz>
        <limit>
          <lower>-1e+16</lower>
          <upper>1e+16</upper>
        </limit>
        <dynamics>
          <spring_reference>0</spring_reference>
          <spring_stiffness>0</spring_stiffness>
        </dynamics>
        <use_parent_model_frame>1</use_parent_model_frame>
      </axis>
    </joint>
    <static>0</static>

    <!-- Plugins -->
    <plugin filename="gz-sim-diff-drive-system"
      name="gz::sim::systems::DiffDrive">
      <left_joint>front_left_wheel_joint</left_joint>
      <right_joint>front_right_wheel_joint</right_joint>
      <wheel_separation>0.5708</wheel_separation>
      <wheel_radius>0.1651</wheel_radius>
      <odom_publish_frequency>50s</odom_publish_frequency>
      <topic>/marble_husky/command/velocity</topic>
    </plugin>
    <plugin filename="gz-sim-odometry-publisher-system"
      name="gz::sim::systems::OdometryPublisher">
      <odom_frame>world</odom_frame>
      <robot_base_frame>marble_husky</robot_base_frame>
      <odom_publish_frequency>50</odom_publish_frequency>
      <odom_topic>marble_husky/odometry</odom_topic>
      <odom_covariance_topic>marble_husky/odometry_with_covariance</odom_covariance_topic>
      <!-- <tf_topic>marble_husky/pose</tf_topic> -->
      <dimensions>3</dimensions>
    </plugin>
    <plugin filename="gz-sim-pose-publisher-system"
      name="gz::sim::systems::PosePublisher">
      <publish_link_pose>true</publish_link_pose>
      <publish_visual_pose>true</publish_visual_pose>
      <publish_collision_pose>true</publish_collision_pose>
      <publish_sensor_pose>true</publish_sensor_pose>
      <publish_model_pose>true</publish_model_pose>
      <publish_nested_model_pose>false</publish_nested_model_pose>
      <use_pose_vector_msg>true</use_pose_vector_msg>
      <static_publisher>true</static_publisher> 
      <static_update_frequency>200</static_update_frequency> 
    </plugin>
  </model>
</sdf>